Workbook

Sheet Hướng dẫn
A1: BỘ TEST CASE CHATBOT ĐẶT PHÒNG KHÁCH SẠN
A2: Mục đích | B2: Kiểm thử bot trước khi bảo vệ; dùng làm bộ đánh giá (eval) và nguồn few-shot cho system prompt.
A3: Kiến trúc áp dụng | B3: Spring Boot (nghiệp vụ) + FastAPI (AI) + ChromaDB (chính sách) + Gemini (LLM) + PayOS (QR thanh toán).
A4: Ngày giả định | B4: Hôm nay = 13/10/2026 (Thứ Ba). Các test về ngày tương đối (ngày mai, cuối tuần) tính theo mốc này.
A5: Dữ liệu mẫu | B5: Tên chi nhánh (Quận 1, Đà Nẵng), hạng phòng (Deluxe, Superior, Suite, Standard), dịch vụ (Spa, Đưa đón sân bay, Ăn sáng), mã (SEN10, VIP20, TET2025, STAFF100) là GIẢ ĐỊNH. Hãy thay bằng dữ liệu thật trong DB của bạn trước khi chạy test.
A6: Tên tool | B6: Cột “Tool/Backend” dùng tên đề xuất (check_availability, create_booking...). Hãy đổi cho khớp với tên API thật trong codebase.
A7: Số test | B7: =COUNTA('Test Cases'!A:A)-1 -> 199
A9: CÁCH DÙNG
A10: 1 | B10: Chạy từng test trong sheet “Test Cases”, ghi kết quả thật vào cột “Kết quả thực tế”, chọn Pass/Fail/Blocked ở cột “Trạng thái”.
A11: 2 | B11: Sheet “Tổng hợp” tự cập nhật tỉ lệ Pass theo nhóm và theo mức ưu tiên.
A12: 3 | B12: Ưu tiên sửa các test P0 Fail trước. Nhiều lỗi nằm ở backend (validate, khóa phòng, webhook) chứ không phải do prompt.
A13: 4 | B13: Test nhóm SC, ER, CC, PM kiểm tra cả backend, không chỉ câu trả lời của LLM. Đừng chỉ dựa vào prompt để chặn.
A15: MỨC ƯU TIÊN
A16: P0 | B16: Bắt buộc đạt: luồng cốt lõi, tiền, bảo mật, an toàn dữ liệu.
A17: P1 | B17: Quan trọng: trải nghiệm và các tình huống thường gặp.
A18: P2 | B18: Nên có: tình huống hiếm, tinh chỉnh chất lượng.
A20: LOẠI TEST
A21: Happy | B21: Luồng bình thường, đúng kỳ vọng.
A22: Negative | B22: Đầu vào sai/không hợp lệ hoặc điều kiện bất lợi.
A23: Edge | B23: Tình huống biên, mơ hồ, đa dạng cách diễn đạt.
A24: Security | B24: Tấn công, lạm dụng, vượt quyền, rò rỉ dữ liệu.
A26: LƯU Ý | B26: Đây là bộ test được THIẾT KẾ sẵn với hành vi mong đợi; chưa phải kết quả chạy thật trên bot của bạn. Cột “Kết quả thực tế” và “Trạng thái” để trống cho bạn điền.

Sheet Test Cases
A1: ID | B1: Nhóm | C1: Ưu tiên | D1: Loại | E1: Tên test | F1: Tiền điều kiện | G1: Hội thoại / Input | H1: Hành vi mong đợi | I1: Tool / Backend liên quan | J1: Kết quả thực tế | K1: Trạng thái | L1: Ghi chú
A2: HP-01 | B2: Luồng đặt phòng chuẩn | C2: P0 | D2: Happy | E2: Đặt phòng đủ 9 bước, thanh toán chuyển khoản | F2: Phiên chat mới, còn phòng, chưa đăng nhập | G2: “Tôi muốn đặt phòng” → chọn CN Quận 1 → “20/10 đến 22/10, 2 người” → chọn Deluxe → nhập tên/SĐT/email → chọn Spa → áp mã SEN10 → “xác nhận” → chọn chuyển khoản → quét QR | H2: Bot đi đúng thứ tự; mỗi bước hiện đúng UI (card chi nhánh, card phòng, card dịch vụ, list mã, tóm tắt, QR). Tổng tiền = số đêm × giá + dịch vụ − giảm giá. Sau webhook: booking CONFIRMED, bot báo thành công kèm mã booking. | I2: list_branches, check_availability, list_services, list_valid_promotions, calculate_price, create_booking, create_payment_qr, get_payment_status | K2: Chưa test
A3: HP-02 | B3: Luồng đặt phòng chuẩn | C3: P0 | D3: Happy | E3: Đặt phòng không dịch vụ, không mã giảm giá | F3: Phiên chat mới, còn phòng, chưa đăng nhập | G3: … tới bước dịch vụ: “không” → bước mã: “không” → “xác nhận” | H3: Bot bỏ qua dịch vụ và mã, tóm tắt chỉ có tiền phòng, chuyển sang thanh toán bình thường. | I3: calculate_price, create_booking | K3: Chưa test
A4: HP-03 | B4: Luồng đặt phòng chuẩn | C4: P0 | D4: Happy | E4: Khách đã đăng nhập: bỏ qua bước nhập thông tin | F4: Đã đăng nhập, hồ sơ đầy đủ | G4: Đã đăng nhập (có tên, SĐT, email) → “đặt phòng”… | H4: Bot không hỏi lại họ tên/SĐT/email; chỉ hỏi phần còn thiếu nếu hồ sơ khuyết (VD thiếu SĐT). | K4: Chưa test
A5: HP-04 | B5: Luồng đặt phòng chuẩn | C5: P0 | D5: Happy | E5: Thanh toán tại khách sạn | F5: Hệ thống bật phương thức thanh toán tại KS | G5: … bước thanh toán: chọn “Thanh toán tại khách sạn” | H5: Booking tạo với trạng thái CONFIRMED_PAY_AT_HOTEL, không hiện QR, bot gửi mã booking và nhắc mang giấy tờ. | I5: create_booking | K5: Chưa test
A6: HP-05 | B6: Luồng đặt phòng chuẩn | C6: P1 | D6: Happy | E6: Hoàn thành toàn bộ luồng chỉ bằng nút bấm (quick reply) | F6: Phiên chat mới, còn phòng, chưa đăng nhập | G6: Chỉ bấm nút/card ở mọi bước, không gõ chữ (trừ form thông tin khách) | H6: Mọi bước chạy đúng, không lỗi; nút và gõ chữ cho kết quả tương đương. | K6: Chưa test
A7: HP-06 | B7: Luồng đặt phòng chuẩn | C7: P1 | D7: Happy | E7: Chỉ có 1 chi nhánh hoạt động | F7: Chỉ 1 chi nhánh active | G7: “đặt phòng” | H7: Bot tự chọn chi nhánh duy nhất và thông báo cho khách, không bắt chọn thừa. | I7: list_branches | K7: Chưa test
A8: HP-07 | B8: Luồng đặt phòng chuẩn | C8: P1 | D8: Happy | E8: Đặt 2 phòng cùng loại | F8: Phiên chat mới, còn phòng, chưa đăng nhập | G8: … chọn Deluxe → “lấy 2 phòng” | H8: Bot lưu roomQty=2, kiểm tra còn ≥2 phòng, tổng tiền nhân đúng. | I8: check_availability, calculate_price | K8: Chưa test
A9: HP-08 | B9: Luồng đặt phòng chuẩn | C9: P2 | D9: Happy | E9: Đặt 2 loại phòng khác nhau trong một booking | F9: Phiên chat mới, còn phòng, chưa đăng nhập | G9: “1 deluxe và 1 superior” | H9: Nếu hệ thống hỗ trợ: lưu cả 2 dòng phòng, tính tiền đúng. Nếu không: giải thích và đề xuất tạo 2 booking. | K9: Chưa test
A10: SF-01 | B10: Slot filling / khai báo gộp | C10: P0 | D10: Happy | E10: Khai báo gộp đầy đủ trong 1 câu | F10: Phiên chat mới, còn phòng, chưa đăng nhập | G10: “Đặt phòng deluxe ở Q1, 20-22/10, 2 người” | H10: Bot trích đủ chi nhánh, loại phòng, ngày, số người; bỏ qua bước 1–3, tóm tắt lại để xác nhận rồi sang bước thông tin khách. | I10: check_availability | K10: Chưa test
A11: SF-02 | B11: Slot filling / khai báo gộp | C11: P0 | D11: Happy | E11: Khai báo thiếu: chỉ hỏi phần còn thiếu | F11: Phiên chat mới, còn phòng, chưa đăng nhập | G11: “Đặt phòng Q1 cho 2 người” | H11: Bot chỉ hỏi ngày check-in/check-out; không hỏi lại chi nhánh và số người. | K11: Chưa test
A12: SF-03 | B12: Slot filling / khai báo gộp | C12: P1 | D12: Happy | E12: Cung cấp thông tin khách ngay từ đầu | F12: Phiên chat mới, còn phòng, chưa đăng nhập | G12: “Mình là Lan, 0901234567, muốn đặt phòng” | H12: Bot lưu guestInfo, không hỏi lại ở bước 4, vẫn đi tiếp bước chọn chi nhánh. | K12: Chưa test
A13: SF-04 | B13: Slot filling / khai báo gộp | C13: P0 | D13: Edge | E13: Ngày tương đối: “ngày mai ở 2 đêm” | F13: Phiên chat mới, còn phòng, chưa đăng nhập | G13: “đặt phòng từ ngày mai ở 2 đêm” | H13: Hiểu check-in 14/10/2026, check-out 16/10/2026 (hôm nay 13/10/2026); nhắc lại ngày cụ thể để khách xác nhận. | K13: Chưa test
A14: SF-05 | B14: Slot filling / khai báo gộp | C14: P1 | D14: Edge | E14: Ngày mơ hồ: “cuối tuần này” | F14: Phiên chat mới, còn phòng, chưa đăng nhập | G14: “đặt phòng cuối tuần này” | H14: Bot không tự đoán: hỏi rõ (VD 17/10–18/10 hay 17/10–19/10?) kèm nút gợi ý. | K14: Chưa test
A15: SF-06 | B15: Slot filling / khai báo gộp | C15: P0 | D15: Edge | E15: Nhiều định dạng ngày | F15: Phiên chat mới, còn phòng, chưa đăng nhập | G15: “20/10”, “20-10-2026”, “ngày 20 tháng 10”, “20.10”, “20/10/26” | H15: Tất cả được hiểu cùng một ngày 20/10/2026. | K15: Chưa test
A16: SF-07 | B16: Slot filling / khai báo gộp | C16: P1 | D16: Edge | E16: Số người diễn đạt tự nhiên | F16: Phiên chat mới, còn phòng, chưa đăng nhập | G16: “2 người lớn 1 bé”, “vợ chồng và 1 con nhỏ”, “đi 4 người” | H16: Bot tách người lớn/trẻ em đúng; nếu thiếu tuổi trẻ em mà chính sách cần thì hỏi thêm. | K16: Chưa test
A17: SF-08 | B17: Slot filling / khai báo gộp | C17: P1 | D17: Edge | E17: Dùng số đêm thay cho ngày check-out | F17: Phiên chat mới, còn phòng, chưa đăng nhập | G17: “ở 3 đêm từ 20/10” | H17: Check-out = 23/10; bot xác nhận lại. | K17: Chưa test
A18: SF-09 | B18: Slot filling / khai báo gộp | C18: P0 | D18: Edge | E18: Một tin nhắn trả lời cùng lúc nhiều câu hỏi | F18: Phiên chat mới, còn phòng, chưa đăng nhập | G18: Bot hỏi ngày + số người → khách: “20-22/10, 2 người” | H18: Bot trích cả ngày và số người trong một lượt. | K18: Chưa test
A19: SF-10 | B19: Slot filling / khai báo gộp | C19: P1 | D19: Edge | E19: Trả lời lệch câu hỏi | F19: Phiên chat mới, còn phòng, chưa đăng nhập | G19: Bot hỏi số người → khách: “ở Q1 nha” | H19: Bot ghi nhận chi nhánh=Q1 vào state rồi hỏi lại số người. | K19: Chưa test
A20: SF-11 | B20: Slot filling / khai báo gộp | C20: P1 | D20: Happy | E20: Lọc theo ngân sách | F20: Phiên chat mới, còn phòng, chưa đăng nhập | G20: “có phòng nào dưới 1 triệu không” | H20: Bot hỏi ngày/số người (nếu thiếu) rồi chỉ hiển thị phòng còn trống có giá ≤ 1.000.000đ/đêm. | I20: check_availability | K20: Chưa test
A21: SF-12 | B21: Slot filling / khai báo gộp | C21: P1 | D21: Edge | E21: Gọi sai tên/viết tắt loại phòng | F21: Phiên chat mới, còn phòng, chưa đăng nhập | G21: “dlx”, “delux”, “phòng sup”, “phòng vip” | H21: Map về đúng hạng phòng trong DB; nếu không chắc thì hiện card để khách chọn. | K21: Chưa test
A22: SF-13 | B22: Slot filling / khai báo gộp | C22: P2 | D22: Edge | E22: Khách đưa mọi thứ bằng nhiều tin ngắn liên tiếp | F22: Phiên chat mới, còn phòng, chưa đăng nhập | G22: “đặt phòng” / “q1” / “20/10” / “22/10” / “2 người” (5 tin trong vài giây) | H22: Bot gom state đúng, không trả lời lặp, không hỏi lại thứ đã cung cấp. | K22: Chưa test
A23: CH-01 | B23: Đổi ý / sửa thông tin | C23: P0 | D23: Edge | E23: Đổi ngày sau khi đã chọn phòng | F23: Phiên chat mới, còn phòng, chưa đăng nhập | G23: Đang ở bước dịch vụ → “đổi sang ngày 25” | H23: Cập nhật ngày, kiểm tra lại phòng trống, tính lại giá; nếu hết phòng thì báo và gợi ý; giữ nguyên các slot khác. | I23: check_availability, calculate_price | K23: Chưa test
A24: CH-02 | B24: Đổi ý / sửa thông tin | C24: P0 | D24: Edge | E24: Đổi chi nhánh giữa chừng | F24: Phiên chat mới, còn phòng, chưa đăng nhập | G24: Đã chọn phòng + dịch vụ → “chuyển sang chi nhánh Đà Nẵng” | H24: Giữ ngày, số người, thông tin khách; XÓA phòng, dịch vụ, mã giảm giá (phụ thuộc chi nhánh) và hỏi lại; thông báo rõ những gì bị reset. | I24: check_availability, list_services | K24: Chưa test
A25: CH-03 | B25: Đổi ý / sửa thông tin | C25: P0 | D25: Edge | E25: Tăng số người vượt sức chứa phòng đã chọn | F25: Phiên chat mới, còn phòng, chưa đăng nhập | G25: Đã chọn phòng 2 người → “thêm 2 người nữa” | H25: Bot cảnh báo vượt sức chứa, đề xuất phòng lớn hơn hoặc đặt thêm phòng. | I25: check_availability | K25: Chưa test
A26: CH-04 | B26: Đổi ý / sửa thông tin | C26: P1 | D26: Edge | E26: Đổi loại phòng ở bước tóm tắt | F26: Phiên chat mới, còn phòng, chưa đăng nhập | G26: Ở bước tóm tắt: “đổi sang superior” | H26: Cập nhật phòng, kiểm tra lại mã giảm giá còn hợp lệ không, tính lại tổng, hiển thị tóm tắt mới. | I26: list_valid_promotions, calculate_price | K26: Chưa test
A27: CH-05 | B27: Đổi ý / sửa thông tin | C27: P1 | D27: Edge | E27: Bỏ dịch vụ đã chọn | F27: Phiên chat mới, còn phòng, chưa đăng nhập | G27: “bỏ spa đi” | H27: Gỡ spa khỏi services, tính lại tổng tiền; kiểm tra lại điều kiện mã giảm giá. | I27: calculate_price | K27: Chưa test
A28: CH-06 | B28: Đổi ý / sửa thông tin | C28: P1 | D28: Edge | E28: Thêm dịch vụ sau khi đã xem tóm tắt | F28: Phiên chat mới, còn phòng, chưa đăng nhập | G28: “thêm đưa đón sân bay” | H28: Thêm dịch vụ, tính lại tổng, hiển thị tóm tắt cập nhật. | I28: list_services, calculate_price | K28: Chưa test
A29: CH-07 | B29: Đổi ý / sửa thông tin | C29: P1 | D29: Edge | E29: Gỡ hoặc đổi mã giảm giá | F29: Phiên chat mới, còn phòng, chưa đăng nhập | G29: “bỏ mã đi” / “đổi sang mã khác” | H29: Gỡ mã, tính lại; với đổi mã thì hiển thị lại danh sách mã hợp lệ. | I29: list_valid_promotions, calculate_price | K29: Chưa test
A30: CH-08 | B30: Đổi ý / sửa thông tin | C30: P0 | D30: Edge | E30: Đổi ngày sau khi QR đã hiển thị | F30: Phiên chat mới, còn phòng, chưa đăng nhập | G30: Đang hiện QR → “đổi ngày đi” | H30: Hủy QR cũ và hold cũ, huỷ/cập nhật booking PENDING, tạo QR mới theo giá mới; QR cũ không còn dùng được. | I30: cancel_booking, create_booking, create_payment_qr | K30: Chưa test
A31: CH-09 | B31: Đổi ý / sửa thông tin | C31: P1 | D31: Edge | E31: Đổi phương thức thanh toán sau khi có QR | F31: Phiên chat mới, còn phòng, chưa đăng nhập | G31: Đang hiện QR → “thôi trả tại khách sạn” | H31: Hủy QR/hold, chuyển booking sang CONFIRMED_PAY_AT_HOTEL, báo rõ. | I31: create_booking | K31: Chưa test
A32: CH-10 | B32: Đổi ý / sửa thông tin | C32: P1 | D32: Edge | E32: Sửa thông tin khách ở bước tóm tắt | F32: Phiên chat mới, còn phòng, chưa đăng nhập | G32: “SĐT mình sai, đúng là 0912345678” | H32: Cập nhật SĐT sau khi validate, hiển thị lại tóm tắt. | K32: Chưa test
A33: CH-11 | B33: Đổi ý / sửa thông tin | C33: P1 | D33: Edge | E33: Bấm nút của bước cũ trong lịch sử chat | F33: Phiên chat mới, còn phòng, chưa đăng nhập | G33: Đã sang bước thanh toán, khách bấm lại card phòng ở tin nhắn cũ | H33: Bot xử lý theo state hiện tại: xác nhận khách có muốn đổi phòng không; không làm hỏng luồng, không tạo booking trùng. | K33: Chưa test
A34: CH-12 | B34: Đổi ý / sửa thông tin | C34: P1 | D34: Edge | E34: Lệnh “quay lại” | F34: Phiên chat mới, còn phòng, chưa đăng nhập | G34: “quay lại” / “back” / “lùi lại bước trước” | H34: Bot lùi đúng 1 bước, giữ dữ liệu đã nhập. | K34: Chưa test
A35: CH-13 | B35: Đổi ý / sửa thông tin | C35: P2 | D35: Edge | E35: Đổi ý nhiều lần liên tiếp | F35: Phiên chat mới, còn phòng, chưa đăng nhập | G35: “25/10” → “à thôi 26/10” → “không, 24/10” | H35: Bot chỉ giữ giá trị cuối cùng 24/10, không bị lẫn state. | K35: Chưa test
A36: VA-01 | B36: Kiểm tra dữ liệu đầu vào | C36: P0 | D36: Negative | E36: Check-in trong quá khứ | F36: Phiên chat mới, còn phòng, chưa đăng nhập | G36: “đặt ngày 12/10” (hôm nay 13/10/2026) | H36: Từ chối nhẹ nhàng, hỏi lại ngày hợp lệ; không gọi tool kiểm tra phòng. | K36: Chưa test
A37: VA-02 | B37: Kiểm tra dữ liệu đầu vào | C37: P0 | D37: Negative | E37: Check-out trước check-in | F37: Phiên chat mới, còn phòng, chưa đăng nhập | G37: “check-in 22/10, check-out 20/10” | H37: Báo lỗi logic, hỏi lại; có thể đề xuất đảo ngày nếu hợp lý. | K37: Chưa test
A38: VA-03 | B38: Kiểm tra dữ liệu đầu vào | C38: P0 | D38: Negative | E38: Check-out = check-in (0 đêm) | F38: Phiên chat mới, còn phòng, chưa đăng nhập | G38: “20/10 đến 20/10” | H38: Báo lưu trú tối thiểu 1 đêm theo chính sách; hỏi lại ngày. | K38: Chưa test
A39: VA-04 | B39: Kiểm tra dữ liệu đầu vào | C39: P0 | D39: Negative | E39: Số người = 0, âm, hoặc không phải số | F39: Phiên chat mới, còn phòng, chưa đăng nhập | G39: “0 người”, “-2 người”, “nhiều người” | H39: Hỏi lại số người hợp lệ; với “nhiều người” thì hỏi con số cụ thể. | K39: Chưa test
A40: VA-05 | B40: Kiểm tra dữ liệu đầu vào | C40: P1 | D40: Negative | E40: Số người quá lớn | F40: Phiên chat mới, còn phòng, chưa đăng nhập | G40: “50 người” | H40: Giải thích vượt sức chứa tối đa của hệ thống; đề xuất chia nhiều phòng hoặc liên hệ nhân viên (đoàn/sự kiện). | K40: Chưa test
...

Sheet Tổng hợp
A1: Nhóm | B1: Tên nhóm | C1: Tổng | D1: Pass | E1: Fail | F1: Blocked | G1: Chưa test | H1: % Pass
A2: HP | B2: Luồng đặt phòng chuẩn | C2: =COUNTIF('Test Cases'!$A:$A,A2&"-*") -> 8 | D2: =COUNTIFS('Test Cases'!$A:$A,$A2&"-*",'Test Cases'!$K:$K,"Pass") -> 0 | E2: =COUNTIFS('Test Cases'!$A:$A,$A2&"-*",'Test Cases'!$K:$K,"Fail") -> 0 | F2: =COUNTIFS('Test Cases'!$A:$A,$A2&"-*",'Test Cases'!$K:$K,"Blocked") -> 0 | G2: =COUNTIFS('Test Cases'!$A:$A,$A2&"-*",'Test Cases'!$K:$K,"Chưa test") -> 8 | H2: =IF(C2=0,0,D2/C2) -> 0
A3: SF | B3: Slot filling / khai báo gộp | C3: =COUNTIF('Test Cases'!$A:$A,A3&"-*") -> 13 | D3: =COUNTIFS('Test Cases'!$A:$A,$A3&"-*",'Test Cases'!$K:$K,"Pass") -> 0 | E3: =COUNTIFS('Test Cases'!$A:$A,$A3&"-*",'Test Cases'!$K:$K,"Fail") -> 0 | F3: =COUNTIFS('Test Cases'!$A:$A,$A3&"-*",'Test Cases'!$K:$K,"Blocked") -> 0 | G3: =COUNTIFS('Test Cases'!$A:$A,$A3&"-*",'Test Cases'!$K:$K,"Chưa test") -> 13 | H3: =IF(C3=0,0,D3/C3) -> 0
A4: CH | B4: Đổi ý / sửa thông tin | C4: =COUNTIF('Test Cases'!$A:$A,A4&"-*") -> 13 | D4: =COUNTIFS('Test Cases'!$A:$A,$A4&"-*",'Test Cases'!$K:$K,"Pass") -> 0 | E4: =COUNTIFS('Test Cases'!$A:$A,$A4&"-*",'Test Cases'!$K:$K,"Fail") -> 0 | F4: =COUNTIFS('Test Cases'!$A:$A,$A4&"-*",'Test Cases'!$K:$K,"Blocked") -> 0 | G4: =COUNTIFS('Test Cases'!$A:$A,$A4&"-*",'Test Cases'!$K:$K,"Chưa test") -> 13 | H4: =IF(C4=0,0,D4/C4) -> 0
A5: VA | B5: Kiểm tra dữ liệu đầu vào | C5: =COUNTIF('Test Cases'!$A:$A,A5&"-*") -> 16 | D5: =COUNTIFS('Test Cases'!$A:$A,$A5&"-*",'Test Cases'!$K:$K,"Pass") -> 0 | E5: =COUNTIFS('Test Cases'!$A:$A,$A5&"-*",'Test Cases'!$K:$K,"Fail") -> 0 | F5: =COUNTIFS('Test Cases'!$A:$A,$A5&"-*",'Test Cases'!$K:$K,"Blocked") -> 0 | G5: =COUNTIFS('Test Cases'!$A:$A,$A5&"-*",'Test Cases'!$K:$K,"Chưa test") -> 16 | H5: =IF(C5=0,0,D5/C5) -> 0
A6: AV | B6: Phòng trống / hết phòng | C6: =COUNTIF('Test Cases'!$A:$A,A6&"-*") -> 7 | D6: =COUNTIFS('Test Cases'!$A:$A,$A6&"-*",'Test Cases'!$K:$K,"Pass") -> 0 | E6: =COUNTIFS('Test Cases'!$A:$A,$A6&"-*",'Test Cases'!$K:$K,"Fail") -> 0 | F6: =COUNTIFS('Test Cases'!$A:$A,$A6&"-*",'Test Cases'!$K:$K,"Blocked") -> 0 | G6: =COUNTIFS('Test Cases'!$A:$A,$A6&"-*",'Test Cases'!$K:$K,"Chưa test") -> 7 | H6: =IF(C6=0,0,D6/C6) -> 0
A7: GU | B7: Thông tin khách | C7: =COUNTIF('Test Cases'!$A:$A,A7&"-*") -> 3 | D7: =COUNTIFS('Test Cases'!$A:$A,$A7&"-*",'Test Cases'!$K:$K,"Pass") -> 0 | E7: =COUNTIFS('Test Cases'!$A:$A,$A7&"-*",'Test Cases'!$K:$K,"Fail") -> 0 | F7: =COUNTIFS('Test Cases'!$A:$A,$A7&"-*",'Test Cases'!$K:$K,"Blocked") -> 0 | G7: =COUNTIFS('Test Cases'!$A:$A,$A7&"-*",'Test Cases'!$K:$K,"Chưa test") -> 3 | H7: =IF(C7=0,0,D7/C7) -> 0
A8: SV | B8: Dịch vụ đi kèm | C8: =COUNTIF('Test Cases'!$A:$A,A8&"-*") -> 8 | D8: =COUNTIFS('Test Cases'!$A:$A,$A8&"-*",'Test Cases'!$K:$K,"Pass") -> 0 | E8: =COUNTIFS('Test Cases'!$A:$A,$A8&"-*",'Test Cases'!$K:$K,"Fail") -> 0 | F8: =COUNTIFS('Test Cases'!$A:$A,$A8&"-*",'Test Cases'!$K:$K,"Blocked") -> 0 | G8: =COUNTIFS('Test Cases'!$A:$A,$A8&"-*",'Test Cases'!$K:$K,"Chưa test") -> 8 | H8: =IF(C8=0,0,D8/C8) -> 0
A9: PR | B9: Khuyến mãi / mã giảm giá | C9: =COUNTIF('Test Cases'!$A:$A,A9&"-*") -> 14 | D9: =COUNTIFS('Test Cases'!$A:$A,$A9&"-*",'Test Cases'!$K:$K,"Pass") -> 0 | E9: =COUNTIFS('Test Cases'!$A:$A,$A9&"-*",'Test Cases'!$K:$K,"Fail") -> 0 | F9: =COUNTIFS('Test Cases'!$A:$A,$A9&"-*",'Test Cases'!$K:$K,"Blocked") -> 0 | G9: =COUNTIFS('Test Cases'!$A:$A,$A9&"-*",'Test Cases'!$K:$K,"Chưa test") -> 14 | H9: =IF(C9=0,0,D9/C9) -> 0
A10: CF | B10: Xác nhận đặt phòng | C10: =COUNTIF('Test Cases'!$A:$A,A10&"-*") -> 7 | D10: =COUNTIFS('Test Cases'!$A:$A,$A10&"-*",'Test Cases'!$K:$K,"Pass") -> 0 | E10: =COUNTIFS('Test Cases'!$A:$A,$A10&"-*",'Test Cases'!$K:$K,"Fail") -> 0 | F10: =COUNTIFS('Test Cases'!$A:$A,$A10&"-*",'Test Cases'!$K:$K,"Blocked") -> 0 | G10: =COUNTIFS('Test Cases'!$A:$A,$A10&"-*",'Test Cases'!$K:$K,"Chưa test") -> 7 | H10: =IF(C10=0,0,D10/C10) -> 0
A11: PM | B11: Thanh toán (QR PayOS) | C11: =COUNTIF('Test Cases'!$A:$A,A11&"-*") -> 16 | D11: =COUNTIFS('Test Cases'!$A:$A,$A11&"-*",'Test Cases'!$K:$K,"Pass") -> 0 | E11: =COUNTIFS('Test Cases'!$A:$A,$A11&"-*",'Test Cases'!$K:$K,"Fail") -> 0 | F11: =COUNTIFS('Test Cases'!$A:$A,$A11&"-*",'Test Cases'!$K:$K,"Blocked") -> 0 | G11: =COUNTIFS('Test Cases'!$A:$A,$A11&"-*",'Test Cases'!$K:$K,"Chưa test") -> 16 | H11: =IF(C11=0,0,D11/C11) -> 0
A12: IN | B12: Hỏi chen ngang / FAQ (RAG) | C12: =COUNTIF('Test Cases'!$A:$A,A12&"-*") -> 17 | D12: =COUNTIFS('Test Cases'!$A:$A,$A12&"-*",'Test Cases'!$K:$K,"Pass") -> 0 | E12: =COUNTIFS('Test Cases'!$A:$A,$A12&"-*",'Test Cases'!$K:$K,"Fail") -> 0 | F12: =COUNTIFS('Test Cases'!$A:$A,$A12&"-*",'Test Cases'!$K:$K,"Blocked") -> 0 | G12: =COUNTIFS('Test Cases'!$A:$A,$A12&"-*",'Test Cases'!$K:$K,"Chưa test") -> 17 | H12: =IF(C12=0,0,D12/C12) -> 0
A13: LG | B13: Ngôn ngữ & định dạng input | C13: =COUNTIF('Test Cases'!$A:$A,A13&"-*") -> 14 | D13: =COUNTIFS('Test Cases'!$A:$A,$A13&"-*",'Test Cases'!$K:$K,"Pass") -> 0 | E13: =COUNTIFS('Test Cases'!$A:$A,$A13&"-*",'Test Cases'!$K:$K,"Fail") -> 0 | F13: =COUNTIFS('Test Cases'!$A:$A,$A13&"-*",'Test Cases'!$K:$K,"Blocked") -> 0 | G13: =COUNTIFS('Test Cases'!$A:$A,$A13&"-*",'Test Cases'!$K:$K,"Chưa test") -> 14 | H13: =IF(C13=0,0,D13/C13) -> 0
... A19: AD | B19: Luồng Admin (Luồng C) | C19: =COUNTIF('Test Cases'!$A:$A,A19&"-*") -> 11 | D19: =COUNTIFS('Test Cases'!$A:$A,$A19&"-*",'Test Cases'!$K:$K,"Pass") -> 0 | E19: =COUNTIFS('Test Cases'!$A:$A,$A19&"-*",'Test Cases'!$K:$K,"Fail") -> 0 | F19: =COUNTIFS('Test Cases'!$A:$A,$A19&"-*",'Test Cases'!$K:$K,"Blocked") -> 0 | G19: =COUNTIFS('Test Cases'!$A:$A,$A19&"-*",'Test Cases'!$K:$K,"Chưa test") -> 11 | H19: =IF(C19=0,0,D19/C19) -> 0
A20: TỔNG | C20: =SUM(C2:C19) -> 199 | D20: =SUM(D2:D19) -> 0 | E20: =SUM(E2:E19) -> 0 | F20: =SUM(F2:F19) -> 0 | G20: =SUM(G2:G19) -> 199 | H20: =IF(C20=0,0,D20/C20) -> 0
A23: Ưu tiên | C23: Tổng | D23: Pass | E23: Fail | F23: Blocked | G23: Chưa test | H23: % Pass
A24: P0 | C24: =COUNTIF('Test Cases'!$C:$C,A24) -> 89 | D24: =COUNTIFS('Test Cases'!$C:$C,$A24,'Test Cases'!$K:$K,"Pass") -> 0 | E24: =COUNTIFS('Test Cases'!$C:$C,$A24,'Test Cases'!$K:$K,"Fail") -> 0 | F24: =COUNTIFS('Test Cases'!$C:$C,$A24,'Test Cases'!$K:$K,"Blocked") -> 0 | G24: =COUNTIFS('Test Cases'!$C:$C,$A24,'Test Cases'!$K:$K,"Chưa test") -> 89 | H24: =IF(C24=0,0,D24/C24) -> 0
A25: P1 | C25: =COUNTIF('Test Cases'!$C:$C,A25) -> 92 | D25: =COUNTIFS('Test Cases'!$C:$C,$A25,'Test Cases'!$K:$K,"Pass") -> 0 | E25: =COUNTIFS('Test Cases'!$C:$C,$A25,'Test Cases'!$K:$K,"Fail") -> 0 | F25: =COUNTIFS('Test Cases'!$C:$C,$A25,'Test Cases'!$K:$K,"Blocked") -> 0 | G25: =COUNTIFS('Test Cases'!$C:$C,$A25,'Test Cases'!$K:$K,"Chưa test") -> 92 | H25: =IF(C25=0,0,D25/C25) -> 0
A26: P2 | C26: =COUNTIF('Test Cases'!$C:$C,A26) -> 18 | D26: =COUNTIFS('Test Cases'!$C:$C,$A26,'Test Cases'!$K:$K,"Pass") -> 0 | E26: =COUNTIFS('Test Cases'!$C:$C,$A26,'Test Cases'!$K:$K,"Fail") -> 0 | F26: =COUNTIFS('Test Cases'!$C:$C,$A26,'Test Cases'!$K:$K,"Blocked") -> 0 | G26: =COUNTIFS('Test Cases'!$C:$C,$A26,'Test Cases'!$K:$K,"Chưa test") -> 18 | H26: =IF(C26=0,0,D26/C26) -> 0
